Traceback (most recent call last):
  File "C:\Users\chawk\AppData\Local\Programs\Python\Python310\lib\site-packages\wandb\sdk\wandb_config.py", line 165, in __getattr__
    return self.__getitem__(key)
  File "C:\Users\chawk\AppData\Local\Programs\Python\Python310\lib\site-packages\wandb\sdk\wandb_config.py", line 130, in __getitem__
    return self._items[key]
KeyError: 'learning_rate'

The above exception was the direct cause of the following exception:

Traceback (most recent call last):
  File "g:\My Drive\Junior Year\CS 175\Project\Code\gym-rocketlander\gym_rocketlander\PPO.py", line 157, in <module>
    main()
  File "g:\My Drive\Junior Year\CS 175\Project\Code\gym-rocketlander\gym_rocketlander\PPO.py", line 128, in main
    learning_rate=config.learning_rate,
  File "C:\Users\chawk\AppData\Local\Programs\Python\Python310\lib\site-packages\wandb\sdk\wandb_config.py", line 167, in __getattr__
    raise AttributeError(
AttributeError: <class 'wandb.sdk.wandb_config.Config'> object has no attribute 'learning_rate'
